Traceback (most recent call last):
  File "/opt/hostedtoolcache/Python/3.9.6/x64/lib/python3.9/site-packages/jupyter_cache/executors/utils.py", line 51, in single_nb_execution
    executenb(
  File "/opt/hostedtoolcache/Python/3.9.6/x64/lib/python3.9/site-packages/nbclient/client.py", line 1112, in execute
    return NotebookClient(nb=nb, resources=resources, km=km, **kwargs).execute()
  File "/opt/hostedtoolcache/Python/3.9.6/x64/lib/python3.9/site-packages/nbclient/util.py", line 74, in wrapped
    return just_run(coro(*args, **kwargs))
  File "/opt/hostedtoolcache/Python/3.9.6/x64/lib/python3.9/site-packages/nbclient/util.py", line 53, in just_run
    return loop.run_until_complete(coro)
  File "/opt/hostedtoolcache/Python/3.9.6/x64/lib/python3.9/asyncio/base_events.py", line 642, in run_until_complete
    return future.result()
  File "/opt/hostedtoolcache/Python/3.9.6/x64/lib/python3.9/site-packages/nbclient/client.py", line 553, in async_execute
    await self.async_execute_cell(
  File "/opt/hostedtoolcache/Python/3.9.6/x64/lib/python3.9/site-packages/nbclient/client.py", line 857, in async_execute_cell
    self._check_raise_for_error(cell, exec_reply)
  File "/opt/hostedtoolcache/Python/3.9.6/x64/lib/python3.9/site-packages/nbclient/client.py", line 760, in _check_raise_for_error
    raise CellExecutionError.from_cell_and_msg(cell, exec_reply_content)
nbclient.exceptions.CellExecutionError: An error occurred while executing the following cell:
------------------
import numpy as np
fea_arrays = np.load('./fea_arrays.npz')
K=fea_arrays['K']
K
------------------

[0;31m---------------------------------------------------------------------------[0m
[0;31mFileNotFoundError[0m                         Traceback (most recent call last)
[0;32m/tmp/ipykernel_3144/2926505998.py[0m in [0;36m<module>[0;34m[0m
[1;32m      1[0m [0;32mimport[0m [0mnumpy[0m [0;32mas[0m [0mnp[0m[0;34m[0m[0;34m[0m[0m
[0;32m----> 2[0;31m [0mfea_arrays[0m [0;34m=[0m [0mnp[0m[0;34m.[0m[0mload[0m[0;34m([0m[0;34m'./fea_arrays.npz'[0m[0;34m)[0m[0;34m[0m[0;34m[0m[0m
[0m[1;32m      3[0m [0mK[0m[0;34m=[0m[0mfea_arrays[0m[0;34m[[0m[0;34m'K'[0m[0;34m][0m[0;34m[0m[0;34m[0m[0m
[1;32m      4[0m [0mK[0m[0;34m[0m[0;34m[0m[0m

[0;32m/opt/hostedtoolcache/Python/3.9.6/x64/lib/python3.9/site-packages/numpy/lib/npyio.py[0m in [0;36mload[0;34m(file, mmap_mode, allow_pickle, fix_imports, encoding)[0m
[1;32m    415[0m             [0mown_fid[0m [0;34m=[0m [0;32mFalse[0m[0;34m[0m[0;34m[0m[0m
[1;32m    416[0m         [0;32melse[0m[0;34m:[0m[0;34m[0m[0;34m[0m[0m
[0;32m--> 417[0;31m             [0mfid[0m [0;34m=[0m [0mstack[0m[0;34m.[0m[0menter_context[0m[0;34m([0m[0mopen[0m[0;34m([0m[0mos_fspath[0m[0;34m([0m[0mfile[0m[0;34m)[0m[0;34m,[0m [0;34m"rb"[0m[0;34m)[0m[0;34m)[0m[0;34m[0m[0;34m[0m[0m
[0m[1;32m    418[0m             [0mown_fid[0m [0;34m=[0m [0;32mTrue[0m[0;34m[0m[0;34m[0m[0m
[1;32m    419[0m [0;34m[0m[0m

[0;31mFileNotFoundError[0m: [Errno 2] No such file or directory: './fea_arrays.npz'
FileNotFoundError: [Errno 2] No such file or directory: './fea_arrays.npz'

